2025-05-17 12:39:08,488 - src.frames_util - ERROR - Unexpected error: HTTPStatusError.__init__() missing 1 required keyword-only argument: 'request'
Traceback (most recent call last):
  File "/home/runner/work/rand-frieren/rand-frieren/src/frames_util.py", line 65, in download_frame
    raise httpx.HTTPStatusError("Rate limit exceeded", response=response)
          ~~~~~~~~~~~~~~~~~~~~~^^^^^^^^^^^^^^^^^^^^^^^^^^^^^^^^^^^^^^^^^^
TypeError: HTTPStatusError.__init__() missing 1 required keyword-only argument: 'request'
2025-05-17 12:51:40,089 - src.frames_util - ERROR - Unexpected error: HTTPStatusError.__init__() missing 1 required keyword-only argument: 'request'
Traceback (most recent call last):
  File "/home/runner/work/rand-frieren/rand-frieren/src/frames_util.py", line 65, in download_frame
    raise httpx.HTTPStatusError("Rate limit exceeded", response=response)
          ~~~~~~~~~~~~~~~~~~~~~^^^^^^^^^^^^^^^^^^^^^^^^^^^^^^^^^^^^^^^^^^
TypeError: HTTPStatusError.__init__() missing 1 required keyword-only argument: 'request'
2025-05-17 21:24:55,641 - src.frames_util - ERROR - Unexpected error: HTTPStatusError.__init__() missing 1 required keyword-only argument: 'request'
Traceback (most recent call last):
  File "/home/runner/work/rand-frieren/rand-frieren/src/frames_util.py", line 65, in download_frame
    raise httpx.HTTPStatusError("Rate limit exceeded", response=response)
          ~~~~~~~~~~~~~~~~~~~~~^^^^^^^^^^^^^^^^^^^^^^^^^^^^^^^^^^^^^^^^^^
TypeError: HTTPStatusError.__init__() missing 1 required keyword-only argument: 'request'
2025-05-17 21:44:36,815 - src.frames_util - ERROR - Unexpected error: HTTPStatusError.__init__() missing 1 required keyword-only argument: 'request'
Traceback (most recent call last):
  File "/home/runner/work/rand-frieren/rand-frieren/src/frames_util.py", line 65, in download_frame
    raise httpx.HTTPStatusError("Rate limit exceeded", response=response)
          ~~~~~~~~~~~~~~~~~~~~~^^^^^^^^^^^^^^^^^^^^^^^^^^^^^^^^^^^^^^^^^^
TypeError: HTTPStatusError.__init__() missing 1 required keyword-only argument: 'request'
2025-05-18 15:44:56,220 - src.frames_util - ERROR - Unexpected error: HTTPStatusError.__init__() missing 1 required keyword-only argument: 'request'
Traceback (most recent call last):
  File "/home/runner/work/rand-frieren/rand-frieren/src/frames_util.py", line 65, in download_frame
    raise httpx.HTTPStatusError("Rate limit exceeded", response=response)
          ~~~~~~~~~~~~~~~~~~~~~^^^^^^^^^^^^^^^^^^^^^^^^^^^^^^^^^^^^^^^^^^
TypeError: HTTPStatusError.__init__() missing 1 required keyword-only argument: 'request'
2025-05-18 21:19:54,421 - src.frames_util - ERROR - Unexpected error: HTTPStatusError.__init__() missing 1 required keyword-only argument: 'request'
Traceback (most recent call last):
  File "/home/runner/work/rand-frieren/rand-frieren/src/frames_util.py", line 65, in download_frame
    raise httpx.HTTPStatusError("Rate limit exceeded", response=response)
          ~~~~~~~~~~~~~~~~~~~~~^^^^^^^^^^^^^^^^^^^^^^^^^^^^^^^^^^^^^^^^^^
TypeError: HTTPStatusError.__init__() missing 1 required keyword-only argument: 'request'
2025-05-18 21:35:10,617 - src.frames_util - ERROR - Unexpected error: HTTPStatusError.__init__() missing 1 required keyword-only argument: 'request'
Traceback (most recent call last):
  File "/home/runner/work/rand-frieren/rand-frieren/src/frames_util.py", line 65, in download_frame
    raise httpx.HTTPStatusError("Rate limit exceeded", response=response)
          ~~~~~~~~~~~~~~~~~~~~~^^^^^^^^^^^^^^^^^^^^^^^^^^^^^^^^^^^^^^^^^^
TypeError: HTTPStatusError.__init__() missing 1 required keyword-only argument: 'request'
2025-05-18 21:45:59,827 - src.frames_util - ERROR - Unexpected error: HTTPStatusError.__init__() missing 1 required keyword-only argument: 'request'
Traceback (most recent call last):
  File "/home/runner/work/rand-frieren/rand-frieren/src/frames_util.py", line 65, in download_frame
    raise httpx.HTTPStatusError("Rate limit exceeded", response=response)
          ~~~~~~~~~~~~~~~~~~~~~^^^^^^^^^^^^^^^^^^^^^^^^^^^^^^^^^^^^^^^^^^
TypeError: HTTPStatusError.__init__() missing 1 required keyword-only argument: 'request'
2025-05-19 01:45:20,711 - src.frames_util - ERROR - Unexpected error: HTTPStatusError.__init__() missing 1 required keyword-only argument: 'request'
Traceback (most recent call last):
  File "/home/runner/work/rand-frieren/rand-frieren/src/frames_util.py", line 65, in download_frame
    raise httpx.HTTPStatusError("Rate limit exceeded", response=response)
          ~~~~~~~~~~~~~~~~~~~~~^^^^^^^^^^^^^^^^^^^^^^^^^^^^^^^^^^^^^^^^^^
TypeError: HTTPStatusError.__init__() missing 1 required keyword-only argument: 'request'
2025-05-19 01:46:31,733 - src.frames_util - ERROR - Unexpected error: HTTPStatusError.__init__() missing 1 required keyword-only argument: 'request'
Traceback (most recent call last):
  File "/home/runner/work/rand-frieren/rand-frieren/src/frames_util.py", line 65, in download_frame
    raise httpx.HTTPStatusError("Rate limit exceeded", response=response)
          ~~~~~~~~~~~~~~~~~~~~~^^^^^^^^^^^^^^^^^^^^^^^^^^^^^^^^^^^^^^^^^^
TypeError: HTTPStatusError.__init__() missing 1 required keyword-only argument: 'request'
2025-05-19 01:50:07,337 - src.frames_util - ERROR - Unexpected error: HTTPStatusError.__init__() missing 1 required keyword-only argument: 'request'
Traceback (most recent call last):
  File "/home/runner/work/rand-frieren/rand-frieren/src/frames_util.py", line 65, in download_frame
    raise httpx.HTTPStatusError("Rate limit exceeded", response=response)
          ~~~~~~~~~~~~~~~~~~~~~^^^^^^^^^^^^^^^^^^^^^^^^^^^^^^^^^^^^^^^^^^
TypeError: HTTPStatusError.__init__() missing 1 required keyword-only argument: 'request'
2025-05-19 02:01:04,301 - src.frames_util - ERROR - Unexpected error: HTTPStatusError.__init__() missing 1 required keyword-only argument: 'request'
Traceback (most recent call last):
  File "/home/runner/work/rand-frieren/rand-frieren/src/frames_util.py", line 65, in download_frame
    raise httpx.HTTPStatusError("Rate limit exceeded", response=response)
          ~~~~~~~~~~~~~~~~~~~~~^^^^^^^^^^^^^^^^^^^^^^^^^^^^^^^^^^^^^^^^^^
TypeError: HTTPStatusError.__init__() missing 1 required keyword-only argument: 'request'
2025-05-19 04:10:00,393 - src.frames_util - ERROR - Unexpected error: HTTPStatusError.__init__() missing 1 required keyword-only argument: 'request'
Traceback (most recent call last):
  File "/home/runner/work/rand-frieren/rand-frieren/src/frames_util.py", line 65, in download_frame
    raise httpx.HTTPStatusError("Rate limit exceeded", response=response)
          ~~~~~~~~~~~~~~~~~~~~~^^^^^^^^^^^^^^^^^^^^^^^^^^^^^^^^^^^^^^^^^^
TypeError: HTTPStatusError.__init__() missing 1 required keyword-only argument: 'request'
2025-05-19 06:54:08,928 - src.frames_util - ERROR - Unexpected error: HTTPStatusError.__init__() missing 1 required keyword-only argument: 'request'
Traceback (most recent call last):
  File "/home/runner/work/rand-frieren/rand-frieren/src/frames_util.py", line 65, in download_frame
    raise httpx.HTTPStatusError("Rate limit exceeded", response=response)
          ~~~~~~~~~~~~~~~~~~~~~^^^^^^^^^^^^^^^^^^^^^^^^^^^^^^^^^^^^^^^^^^
TypeError: HTTPStatusError.__init__() missing 1 required keyword-only argument: 'request'
2025-05-19 06:55:19,945 - src.frames_util - ERROR - Unexpected error: HTTPStatusError.__init__() missing 1 required keyword-only argument: 'request'
Traceback (most recent call last):
  File "/home/runner/work/rand-frieren/rand-frieren/src/frames_util.py", line 65, in download_frame
    raise httpx.HTTPStatusError("Rate limit exceeded", response=response)
          ~~~~~~~~~~~~~~~~~~~~~^^^^^^^^^^^^^^^^^^^^^^^^^^^^^^^^^^^^^^^^^^
TypeError: HTTPStatusError.__init__() missing 1 required keyword-only argument: 'request'
2025-05-19 21:23:55,875 - src.frames_util - ERROR - Unexpected error: HTTPStatusError.__init__() missing 1 required keyword-only argument: 'request'
Traceback (most recent call last):
  File "/home/runner/work/rand-frieren/rand-frieren/src/frames_util.py", line 65, in download_frame
    raise httpx.HTTPStatusError("Rate limit exceeded", response=response)
          ~~~~~~~~~~~~~~~~~~~~~^^^^^^^^^^^^^^^^^^^^^^^^^^^^^^^^^^^^^^^^^^
TypeError: HTTPStatusError.__init__() missing 1 required keyword-only argument: 'request'
2025-05-19 21:34:14,279 - src.frames_util - ERROR - Unexpected error: HTTPStatusError.__init__() missing 1 required keyword-only argument: 'request'
Traceback (most recent call last):
  File "/home/runner/work/rand-frieren/rand-frieren/src/frames_util.py", line 65, in download_frame
    raise httpx.HTTPStatusError("Rate limit exceeded", response=response)
          ~~~~~~~~~~~~~~~~~~~~~^^^^^^^^^^^^^^^^^^^^^^^^^^^^^^^^^^^^^^^^^^
TypeError: HTTPStatusError.__init__() missing 1 required keyword-only argument: 'request'
2025-05-19 21:47:01,477 - src.frames_util - ERROR - Unexpected error: HTTPStatusError.__init__() missing 1 required keyword-only argument: 'request'
Traceback (most recent call last):
  File "/home/runner/work/rand-frieren/rand-frieren/src/frames_util.py", line 65, in download_frame
    raise httpx.HTTPStatusError("Rate limit exceeded", response=response)
          ~~~~~~~~~~~~~~~~~~~~~^^^^^^^^^^^^^^^^^^^^^^^^^^^^^^^^^^^^^^^^^^
TypeError: HTTPStatusError.__init__() missing 1 required keyword-only argument: 'request'
2025-05-27 04:09:16,198 - src.frames_util - ERROR - HTTP error while downloading frame 5144 from episode 16: 404 - 404: Not Found
NoneType: None
2025-05-27 04:09:16,199 - __main__ - ERROR - Error: Frame 5144 from episode 16 not found.
2025-05-27 04:09:16,199 - __main__ - ERROR - ✖ Error processing frame (__main__)
2025-06-22 09:26:30,029 - src.frames_util - ERROR - HTTP error while downloading frame 5081 from episode 16: 404 - 404: Not Found
NoneType: None
2025-06-22 09:26:30,030 - __main__ - ERROR - Error: Frame 5081 from episode 16 not found.
2025-06-22 09:26:30,030 - __main__ - ERROR - ✖ Error processing frame
2025-06-24 06:36:12,071 - src.frames_util - ERROR - HTTP error while downloading frame 5098 from episode 16: 404 - 404: Not Found
NoneType: None
2025-06-24 06:36:12,072 - __main__ - ERROR - Error: Frame 5098 from episode 16 not found.
2025-06-24 06:36:12,072 - __main__ - ERROR - ✖ Error processing frame
2025-07-11 18:34:31,969 - src.poster - ERROR - ✖ Error posting frame: [Errno 101] Network is unreachable
2025-07-11 18:34:31,970 - __main__ - ERROR - ✖ Failed to post frame data
2025-07-15 01:54:27,289 - src.frames_util - ERROR - HTTP error while downloading frame 5136 from episode 16: 404 - 404: Not Found
NoneType: None
2025-07-15 01:54:27,289 - __main__ - ERROR - Error: Frame 5136 from episode 16 not found.
2025-07-15 01:54:27,289 - __main__ - ERROR - ✖ Error processing frame
2025-07-27 18:28:50,999 - src.frames_util - ERROR - HTTP error while downloading frame 5101 from episode 16: 404 - 404: Not Found
NoneType: None
2025-07-27 18:28:51,000 - __main__ - ERROR - Error: Frame 5101 from episode 16 not found.
2025-07-27 18:28:51,000 - __main__ - ERROR - ✖ Error processing frame
2025-07-30 04:22:55,651 - src.frames_util - ERROR - HTTP error while downloading frame 5135 from episode 16: 404 - 404: Not Found
NoneType: None
2025-07-30 04:22:55,651 - __main__ - ERROR - Error: Frame 5135 from episode 16 not found.
2025-07-30 04:22:55,651 - __main__ - ERROR - ✖ Error processing frame
2025-08-05 04:28:59,705 - src.frames_util - ERROR - HTTP error while downloading frame 5067 from episode 16: 404 - 404: Not Found
NoneType: None
2025-08-05 04:28:59,706 - __main__ - ERROR - Error: Frame 5067 from episode 16 not found.
2025-08-05 04:28:59,706 - __main__ - ERROR - ✖ Error processing frame
2025-08-15 09:29:49,017 - src.poster - ERROR - ✖ Error posting random crop: Server error '500 Internal Server Error' for url 'https://graph.facebook.com/v21.0//122274691112068249/comments?access_token=EAAMplsD3FFQBO9dn0XRGPN7Cx41kiuvXbA8fyZB9u9jvNPVrOksZAZBIKfftiLnReqc8AXVG3HpIfeHacIXOR9VaeJWF5oIZC9AKpXLj76PwkVMchfoCmOtUwkWzuvWKsidGi1osFocBi0xlponZC8jJzqwcnbcsp155zjaj4cTaZC4RudGec1ZCC9qJlZAAmHcZD&message=Random+Crop.+%5B419x419+~+X%3A+313%2C+Y%3A+144%5D'
For more information check: https://developer.mozilla.org/en-US/docs/Web/HTTP/Status/500
2025-08-15 09:32:12,685 - src.poster - ERROR - ✖ Error posting random crop: Server error '500 Internal Server Error' for url 'https://graph.facebook.com/v21.0//122274691742068249/comments?access_token=EAAMplsD3FFQBO9dn0XRGPN7Cx41kiuvXbA8fyZB9u9jvNPVrOksZAZBIKfftiLnReqc8AXVG3HpIfeHacIXOR9VaeJWF5oIZC9AKpXLj76PwkVMchfoCmOtUwkWzuvWKsidGi1osFocBi0xlponZC8jJzqwcnbcsp155zjaj4cTaZC4RudGec1ZCC9qJlZAAmHcZD&message=Random+Crop.+%5B536x536+~+X%3A+326%2C+Y%3A+457%5D'
For more information check: https://developer.mozilla.org/en-US/docs/Web/HTTP/Status/500
2025-08-20 21:37:19,547 - src.frames_util - ERROR - HTTP error while downloading frame 5076 from episode 16: 404 - 404: Not Found
NoneType: None
2025-08-20 21:37:19,547 - __main__ - ERROR - Error: Frame 5076 from episode 16 not found.
2025-08-20 21:37:19,547 - __main__ - ERROR - ✖ Error processing frame
2025-08-23 03:35:40,046 - src.poster - ERROR - ✖ Error posting frame: [Errno 101] Network is unreachable
2025-08-23 03:35:40,046 - __main__ - ERROR - ✖ Failed to post frame data
2025-08-23 03:40:34,334 - src.poster - ERROR - ✖ Error posting frame: [Errno 101] Network is unreachable
2025-08-23 03:40:34,335 - __main__ - ERROR - ✖ Failed to post frame data
2025-08-25 12:41:30,847 - src.frames_util - ERROR - Request error while downloading frame 148 from episode 22: [Errno 104] Connection reset by peer
Traceback (most recent call last):
  File "/opt/hostedtoolcache/Python/3.13.7/x64/lib/python3.13/site-packages/httpx/_transports/default.py", line 101, in map_httpcore_exceptions
    yield
  File "/opt/hostedtoolcache/Python/3.13.7/x64/lib/python3.13/site-packages/httpx/_transports/default.py", line 250, in handle_request
    resp = self._pool.handle_request(req)
  File "/opt/hostedtoolcache/Python/3.13.7/x64/lib/python3.13/site-packages/httpcore/_sync/connection_pool.py", line 256, in handle_request
    raise exc from None
  File "/opt/hostedtoolcache/Python/3.13.7/x64/lib/python3.13/site-packages/httpcore/_sync/connection_pool.py", line 236, in handle_request
    response = connection.handle_request(
        pool_request.request
    )
  File "/opt/hostedtoolcache/Python/3.13.7/x64/lib/python3.13/site-packages/httpcore/_sync/connection.py", line 101, in handle_request
    raise exc
  File "/opt/hostedtoolcache/Python/3.13.7/x64/lib/python3.13/site-packages/httpcore/_sync/connection.py", line 78, in handle_request
    stream = self._connect(request)
  File "/opt/hostedtoolcache/Python/3.13.7/x64/lib/python3.13/site-packages/httpcore/_sync/connection.py", line 156, in _connect
    stream = stream.start_tls(**kwargs)
  File "/opt/hostedtoolcache/Python/3.13.7/x64/lib/python3.13/site-packages/httpcore/_backends/sync.py", line 154, in start_tls
    with map_exceptions(exc_map):
         ~~~~~~~~~~~~~~^^^^^^^^^
  File "/opt/hostedtoolcache/Python/3.13.7/x64/lib/python3.13/contextlib.py", line 162, in __exit__
    self.gen.throw(value)
    ~~~~~~~~~~~~~~^^^^^^^
  File "/opt/hostedtoolcache/Python/3.13.7/x64/lib/python3.13/site-packages/httpcore/_exceptions.py", line 14, in map_exceptions
    raise to_exc(exc) from exc
httpcore.ConnectError: [Errno 104] Connection reset by peer

The above exception was the direct cause of the following exception:

Traceback (most recent call last):
  File "/home/runner/work/rand-frieren/rand-frieren/src/frames_util.py", line 61, in download_frame
    response = client.get(frame_url)
  File "/opt/hostedtoolcache/Python/3.13.7/x64/lib/python3.13/site-packages/httpx/_client.py", line 1053, in get
    return self.request(
           ~~~~~~~~~~~~^
        "GET",
        ^^^^^^
    ...<7 lines>...
        extensions=extensions,
        ^^^^^^^^^^^^^^^^^^^^^^
    )
    ^
  File "/opt/hostedtoolcache/Python/3.13.7/x64/lib/python3.13/site-packages/httpx/_client.py", line 825, in request
    return self.send(request, auth=auth, follow_redirects=follow_redirects)
           ~~~~~~~~~^^^^^^^^^^^^^^^^^^^^^^^^^^^^^^^^^^^^^^^^^^^^^^^^^^^^^^^
  File "/opt/hostedtoolcache/Python/3.13.7/x64/lib/python3.13/site-packages/httpx/_client.py", line 914, in send
    response = self._send_handling_auth(
        request,
    ...<2 lines>...
        history=[],
    )
  File "/opt/hostedtoolcache/Python/3.13.7/x64/lib/python3.13/site-packages/httpx/_client.py", line 942, in _send_handling_auth
    response = self._send_handling_redirects(
        request,
        follow_redirects=follow_redirects,
        history=history,
    )
  File "/opt/hostedtoolcache/Python/3.13.7/x64/lib/python3.13/site-packages/httpx/_client.py", line 979, in _send_handling_redirects
    response = self._send_single_request(request)
  File "/opt/hostedtoolcache/Python/3.13.7/x64/lib/python3.13/site-packages/httpx/_client.py", line 1014, in _send_single_request
    response = transport.handle_request(request)
  File "/opt/hostedtoolcache/Python/3.13.7/x64/lib/python3.13/site-packages/httpx/_transports/default.py", line 249, in handle_request
    with map_httpcore_exceptions():
         ~~~~~~~~~~~~~~~~~~~~~~~^^
  File "/opt/hostedtoolcache/Python/3.13.7/x64/lib/python3.13/contextlib.py", line 162, in __exit__
    self.gen.throw(value)
    ~~~~~~~~~~~~~~^^^^^^^
  File "/opt/hostedtoolcache/Python/3.13.7/x64/lib/python3.13/site-packages/httpx/_transports/default.py", line 118, in map_httpcore_exceptions
    raise mapped_exc(message) from exc
httpx.ConnectError: [Errno 104] Connection reset by peer
2025-08-25 12:41:30,859 - __main__ - ERROR - Error: Frame 148 from episode 22 not found.
2025-08-25 12:41:30,859 - __main__ - ERROR - ✖ Error processing frame
2025-08-25 12:46:30,131 - src.frames_util - ERROR - Request error while downloading frame 3338 from episode 14: [Errno 104] Connection reset by peer
Traceback (most recent call last):
  File "/opt/hostedtoolcache/Python/3.13.7/x64/lib/python3.13/site-packages/httpx/_transports/default.py", line 101, in map_httpcore_exceptions
    yield
  File "/opt/hostedtoolcache/Python/3.13.7/x64/lib/python3.13/site-packages/httpx/_transports/default.py", line 250, in handle_request
    resp = self._pool.handle_request(req)
  File "/opt/hostedtoolcache/Python/3.13.7/x64/lib/python3.13/site-packages/httpcore/_sync/connection_pool.py", line 256, in handle_request
    raise exc from None
  File "/opt/hostedtoolcache/Python/3.13.7/x64/lib/python3.13/site-packages/httpcore/_sync/connection_pool.py", line 236, in handle_request
    response = connection.handle_request(
        pool_request.request
    )
  File "/opt/hostedtoolcache/Python/3.13.7/x64/lib/python3.13/site-packages/httpcore/_sync/connection.py", line 101, in handle_request
    raise exc
  File "/opt/hostedtoolcache/Python/3.13.7/x64/lib/python3.13/site-packages/httpcore/_sync/connection.py", line 78, in handle_request
    stream = self._connect(request)
  File "/opt/hostedtoolcache/Python/3.13.7/x64/lib/python3.13/site-packages/httpcore/_sync/connection.py", line 156, in _connect
    stream = stream.start_tls(**kwargs)
  File "/opt/hostedtoolcache/Python/3.13.7/x64/lib/python3.13/site-packages/httpcore/_backends/sync.py", line 154, in start_tls
    with map_exceptions(exc_map):
         ~~~~~~~~~~~~~~^^^^^^^^^
  File "/opt/hostedtoolcache/Python/3.13.7/x64/lib/python3.13/contextlib.py", line 162, in __exit__
    self.gen.throw(value)
    ~~~~~~~~~~~~~~^^^^^^^
  File "/opt/hostedtoolcache/Python/3.13.7/x64/lib/python3.13/site-packages/httpcore/_exceptions.py", line 14, in map_exceptions
    raise to_exc(exc) from exc
httpcore.ConnectError: [Errno 104] Connection reset by peer

The above exception was the direct cause of the following exception:

Traceback (most recent call last):
  File "/home/runner/work/rand-frieren/rand-frieren/src/frames_util.py", line 61, in download_frame
    response = client.get(frame_url)
  File "/opt/hostedtoolcache/Python/3.13.7/x64/lib/python3.13/site-packages/httpx/_client.py", line 1053, in get
    return self.request(
           ~~~~~~~~~~~~^
        "GET",
        ^^^^^^
    ...<7 lines>...
        extensions=extensions,
        ^^^^^^^^^^^^^^^^^^^^^^
    )
    ^
  File "/opt/hostedtoolcache/Python/3.13.7/x64/lib/python3.13/site-packages/httpx/_client.py", line 825, in request
    return self.send(request, auth=auth, follow_redirects=follow_redirects)
           ~~~~~~~~~^^^^^^^^^^^^^^^^^^^^^^^^^^^^^^^^^^^^^^^^^^^^^^^^^^^^^^^
  File "/opt/hostedtoolcache/Python/3.13.7/x64/lib/python3.13/site-packages/httpx/_client.py", line 914, in send
    response = self._send_handling_auth(
        request,
    ...<2 lines>...
        history=[],
    )
  File "/opt/hostedtoolcache/Python/3.13.7/x64/lib/python3.13/site-packages/httpx/_client.py", line 942, in _send_handling_auth
    response = self._send_handling_redirects(
        request,
        follow_redirects=follow_redirects,
        history=history,
    )
  File "/opt/hostedtoolcache/Python/3.13.7/x64/lib/python3.13/site-packages/httpx/_client.py", line 979, in _send_handling_redirects
    response = self._send_single_request(request)
  File "/opt/hostedtoolcache/Python/3.13.7/x64/lib/python3.13/site-packages/httpx/_client.py", line 1014, in _send_single_request
    response = transport.handle_request(request)
  File "/opt/hostedtoolcache/Python/3.13.7/x64/lib/python3.13/site-packages/httpx/_transports/default.py", line 249, in handle_request
    with map_httpcore_exceptions():
         ~~~~~~~~~~~~~~~~~~~~~~~^^
  File "/opt/hostedtoolcache/Python/3.13.7/x64/lib/python3.13/contextlib.py", line 162, in __exit__
    self.gen.throw(value)
    ~~~~~~~~~~~~~~^^^^^^^
  File "/opt/hostedtoolcache/Python/3.13.7/x64/lib/python3.13/site-packages/httpx/_transports/default.py", line 118, in map_httpcore_exceptions
    raise mapped_exc(message) from exc
httpx.ConnectError: [Errno 104] Connection reset by peer
2025-08-25 12:46:30,133 - __main__ - ERROR - Error: Frame 3338 from episode 14 not found.
2025-08-25 12:46:30,133 - __main__ - ERROR - ✖ Error processing frame
2025-08-25 18:46:04,790 - src.frames_util - ERROR - HTTP error while downloading frame 5074 from episode 16: 404 - 404: Not Found
NoneType: None
2025-08-25 18:46:04,790 - __main__ - ERROR - Error: Frame 5074 from episode 16 not found.
2025-08-25 18:46:04,790 - __main__ - ERROR - ✖ Error processing frame
2025-09-08 09:23:17,720 - src.facebook - ERROR - Tentativa 1 falhou: The read operation timed out
2025-09-22 06:37:52,068 - src.frames_util - ERROR - Request error while downloading frame 2219 from episode 23: [Errno 104] Connection reset by peer
Traceback (most recent call last):
  File "/opt/hostedtoolcache/Python/3.13.7/x64/lib/python3.13/site-packages/httpx/_transports/default.py", line 101, in map_httpcore_exceptions
    yield
  File "/opt/hostedtoolcache/Python/3.13.7/x64/lib/python3.13/site-packages/httpx/_transports/default.py", line 250, in handle_request
    resp = self._pool.handle_request(req)
  File "/opt/hostedtoolcache/Python/3.13.7/x64/lib/python3.13/site-packages/httpcore/_sync/connection_pool.py", line 256, in handle_request
    raise exc from None
  File "/opt/hostedtoolcache/Python/3.13.7/x64/lib/python3.13/site-packages/httpcore/_sync/connection_pool.py", line 236, in handle_request
    response = connection.handle_request(
        pool_request.request
    )
  File "/opt/hostedtoolcache/Python/3.13.7/x64/lib/python3.13/site-packages/httpcore/_sync/connection.py", line 101, in handle_request
    raise exc
  File "/opt/hostedtoolcache/Python/3.13.7/x64/lib/python3.13/site-packages/httpcore/_sync/connection.py", line 78, in handle_request
    stream = self._connect(request)
  File "/opt/hostedtoolcache/Python/3.13.7/x64/lib/python3.13/site-packages/httpcore/_sync/connection.py", line 156, in _connect
    stream = stream.start_tls(**kwargs)
  File "/opt/hostedtoolcache/Python/3.13.7/x64/lib/python3.13/site-packages/httpcore/_backends/sync.py", line 154, in start_tls
    with map_exceptions(exc_map):
         ~~~~~~~~~~~~~~^^^^^^^^^
  File "/opt/hostedtoolcache/Python/3.13.7/x64/lib/python3.13/contextlib.py", line 162, in __exit__
    self.gen.throw(value)
    ~~~~~~~~~~~~~~^^^^^^^
  File "/opt/hostedtoolcache/Python/3.13.7/x64/lib/python3.13/site-packages/httpcore/_exceptions.py", line 14, in map_exceptions
    raise to_exc(exc) from exc
httpcore.ConnectError: [Errno 104] Connection reset by peer

The above exception was the direct cause of the following exception:

Traceback (most recent call last):
  File "/home/runner/work/rand-frieren/rand-frieren/src/frames_util.py", line 61, in download_frame
    response = client.get(frame_url)
  File "/opt/hostedtoolcache/Python/3.13.7/x64/lib/python3.13/site-packages/httpx/_client.py", line 1053, in get
    return self.request(
           ~~~~~~~~~~~~^
        "GET",
        ^^^^^^
    ...<7 lines>...
        extensions=extensions,
        ^^^^^^^^^^^^^^^^^^^^^^
    )
    ^
  File "/opt/hostedtoolcache/Python/3.13.7/x64/lib/python3.13/site-packages/httpx/_client.py", line 825, in request
    return self.send(request, auth=auth, follow_redirects=follow_redirects)
           ~~~~~~~~~^^^^^^^^^^^^^^^^^^^^^^^^^^^^^^^^^^^^^^^^^^^^^^^^^^^^^^^
  File "/opt/hostedtoolcache/Python/3.13.7/x64/lib/python3.13/site-packages/httpx/_client.py", line 914, in send
    response = self._send_handling_auth(
        request,
    ...<2 lines>...
        history=[],
    )
  File "/opt/hostedtoolcache/Python/3.13.7/x64/lib/python3.13/site-packages/httpx/_client.py", line 942, in _send_handling_auth
    response = self._send_handling_redirects(
        request,
        follow_redirects=follow_redirects,
        history=history,
    )
  File "/opt/hostedtoolcache/Python/3.13.7/x64/lib/python3.13/site-packages/httpx/_client.py", line 979, in _send_handling_redirects
    response = self._send_single_request(request)
  File "/opt/hostedtoolcache/Python/3.13.7/x64/lib/python3.13/site-packages/httpx/_client.py", line 1014, in _send_single_request
    response = transport.handle_request(request)
  File "/opt/hostedtoolcache/Python/3.13.7/x64/lib/python3.13/site-packages/httpx/_transports/default.py", line 249, in handle_request
    with map_httpcore_exceptions():
         ~~~~~~~~~~~~~~~~~~~~~~~^^
  File "/opt/hostedtoolcache/Python/3.13.7/x64/lib/python3.13/contextlib.py", line 162, in __exit__
    self.gen.throw(value)
    ~~~~~~~~~~~~~~^^^^^^^
  File "/opt/hostedtoolcache/Python/3.13.7/x64/lib/python3.13/site-packages/httpx/_transports/default.py", line 118, in map_httpcore_exceptions
    raise mapped_exc(message) from exc
httpx.ConnectError: [Errno 104] Connection reset by peer
2025-09-22 06:37:52,109 - __main__ - ERROR - Error: Frame 2219 from episode 23 not found.
2025-09-22 06:37:52,109 - __main__ - ERROR - ✖ Error processing frame
2025-09-22 06:38:03,120 - src.frames_util - ERROR - Request error while downloading frame 1235 from episode 3: [Errno 104] Connection reset by peer
Traceback (most recent call last):
  File "/opt/hostedtoolcache/Python/3.13.7/x64/lib/python3.13/site-packages/httpx/_transports/default.py", line 101, in map_httpcore_exceptions
    yield
  File "/opt/hostedtoolcache/Python/3.13.7/x64/lib/python3.13/site-packages/httpx/_transports/default.py", line 250, in handle_request
    resp = self._pool.handle_request(req)
  File "/opt/hostedtoolcache/Python/3.13.7/x64/lib/python3.13/site-packages/httpcore/_sync/connection_pool.py", line 256, in handle_request
    raise exc from None
  File "/opt/hostedtoolcache/Python/3.13.7/x64/lib/python3.13/site-packages/httpcore/_sync/connection_pool.py", line 236, in handle_request
    response = connection.handle_request(
        pool_request.request
    )
  File "/opt/hostedtoolcache/Python/3.13.7/x64/lib/python3.13/site-packages/httpcore/_sync/connection.py", line 101, in handle_request
    raise exc
  File "/opt/hostedtoolcache/Python/3.13.7/x64/lib/python3.13/site-packages/httpcore/_sync/connection.py", line 78, in handle_request
    stream = self._connect(request)
  File "/opt/hostedtoolcache/Python/3.13.7/x64/lib/python3.13/site-packages/httpcore/_sync/connection.py", line 156, in _connect
    stream = stream.start_tls(**kwargs)
  File "/opt/hostedtoolcache/Python/3.13.7/x64/lib/python3.13/site-packages/httpcore/_backends/sync.py", line 154, in start_tls
    with map_exceptions(exc_map):
         ~~~~~~~~~~~~~~^^^^^^^^^
  File "/opt/hostedtoolcache/Python/3.13.7/x64/lib/python3.13/contextlib.py", line 162, in __exit__
    self.gen.throw(value)
    ~~~~~~~~~~~~~~^^^^^^^
  File "/opt/hostedtoolcache/Python/3.13.7/x64/lib/python3.13/site-packages/httpcore/_exceptions.py", line 14, in map_exceptions
    raise to_exc(exc) from exc
httpcore.ConnectError: [Errno 104] Connection reset by peer

The above exception was the direct cause of the following exception:

Traceback (most recent call last):
  File "/home/runner/work/rand-frieren/rand-frieren/src/frames_util.py", line 61, in download_frame
    response = client.get(frame_url)
  File "/opt/hostedtoolcache/Python/3.13.7/x64/lib/python3.13/site-packages/httpx/_client.py", line 1053, in get
    return self.request(
           ~~~~~~~~~~~~^
        "GET",
        ^^^^^^
    ...<7 lines>...
        extensions=extensions,
        ^^^^^^^^^^^^^^^^^^^^^^
    )
    ^
  File "/opt/hostedtoolcache/Python/3.13.7/x64/lib/python3.13/site-packages/httpx/_client.py", line 825, in request
    return self.send(request, auth=auth, follow_redirects=follow_redirects)
           ~~~~~~~~~^^^^^^^^^^^^^^^^^^^^^^^^^^^^^^^^^^^^^^^^^^^^^^^^^^^^^^^
  File "/opt/hostedtoolcache/Python/3.13.7/x64/lib/python3.13/site-packages/httpx/_client.py", line 914, in send
    response = self._send_handling_auth(
        request,
    ...<2 lines>...
        history=[],
    )
  File "/opt/hostedtoolcache/Python/3.13.7/x64/lib/python3.13/site-packages/httpx/_client.py", line 942, in _send_handling_auth
    response = self._send_handling_redirects(
        request,
        follow_redirects=follow_redirects,
        history=history,
    )
  File "/opt/hostedtoolcache/Python/3.13.7/x64/lib/python3.13/site-packages/httpx/_client.py", line 979, in _send_handling_redirects
    response = self._send_single_request(request)
  File "/opt/hostedtoolcache/Python/3.13.7/x64/lib/python3.13/site-packages/httpx/_client.py", line 1014, in _send_single_request
    response = transport.handle_request(request)
  File "/opt/hostedtoolcache/Python/3.13.7/x64/lib/python3.13/site-packages/httpx/_transports/default.py", line 249, in handle_request
    with map_httpcore_exceptions():
         ~~~~~~~~~~~~~~~~~~~~~~~^^
  File "/opt/hostedtoolcache/Python/3.13.7/x64/lib/python3.13/contextlib.py", line 162, in __exit__
    self.gen.throw(value)
    ~~~~~~~~~~~~~~^^^^^^^
  File "/opt/hostedtoolcache/Python/3.13.7/x64/lib/python3.13/site-packages/httpx/_transports/default.py", line 118, in map_httpcore_exceptions
    raise mapped_exc(message) from exc
httpx.ConnectError: [Errno 104] Connection reset by peer
2025-09-22 06:38:03,123 - __main__ - ERROR - Error: Frame 1235 from episode 3 not found.
2025-09-22 06:38:03,123 - __main__ - ERROR - ✖ Error processing frame
2025-09-22 06:40:38,531 - src.frames_util - ERROR - Request error while downloading frame 4354 from episode 27: [Errno 104] Connection reset by peer
Traceback (most recent call last):
  File "/opt/hostedtoolcache/Python/3.13.7/x64/lib/python3.13/site-packages/httpx/_transports/default.py", line 101, in map_httpcore_exceptions
    yield
  File "/opt/hostedtoolcache/Python/3.13.7/x64/lib/python3.13/site-packages/httpx/_transports/default.py", line 250, in handle_request
    resp = self._pool.handle_request(req)
  File "/opt/hostedtoolcache/Python/3.13.7/x64/lib/python3.13/site-packages/httpcore/_sync/connection_pool.py", line 256, in handle_request
    raise exc from None
  File "/opt/hostedtoolcache/Python/3.13.7/x64/lib/python3.13/site-packages/httpcore/_sync/connection_pool.py", line 236, in handle_request
    response = connection.handle_request(
        pool_request.request
    )
  File "/opt/hostedtoolcache/Python/3.13.7/x64/lib/python3.13/site-packages/httpcore/_sync/connection.py", line 101, in handle_request
    raise exc
  File "/opt/hostedtoolcache/Python/3.13.7/x64/lib/python3.13/site-packages/httpcore/_sync/connection.py", line 78, in handle_request
    stream = self._connect(request)
  File "/opt/hostedtoolcache/Python/3.13.7/x64/lib/python3.13/site-packages/httpcore/_sync/connection.py", line 156, in _connect
    stream = stream.start_tls(**kwargs)
  File "/opt/hostedtoolcache/Python/3.13.7/x64/lib/python3.13/site-packages/httpcore/_backends/sync.py", line 154, in start_tls
    with map_exceptions(exc_map):
         ~~~~~~~~~~~~~~^^^^^^^^^
  File "/opt/hostedtoolcache/Python/3.13.7/x64/lib/python3.13/contextlib.py", line 162, in __exit__
    self.gen.throw(value)
    ~~~~~~~~~~~~~~^^^^^^^
  File "/opt/hostedtoolcache/Python/3.13.7/x64/lib/python3.13/site-packages/httpcore/_exceptions.py", line 14, in map_exceptions
    raise to_exc(exc) from exc
httpcore.ConnectError: [Errno 104] Connection reset by peer

The above exception was the direct cause of the following exception:

Traceback (most recent call last):
  File "/home/runner/work/rand-frieren/rand-frieren/src/frames_util.py", line 61, in download_frame
    response = client.get(frame_url)
  File "/opt/hostedtoolcache/Python/3.13.7/x64/lib/python3.13/site-packages/httpx/_client.py", line 1053, in get
    return self.request(
           ~~~~~~~~~~~~^
        "GET",
        ^^^^^^
    ...<7 lines>...
        extensions=extensions,
        ^^^^^^^^^^^^^^^^^^^^^^
    )
    ^
  File "/opt/hostedtoolcache/Python/3.13.7/x64/lib/python3.13/site-packages/httpx/_client.py", line 825, in request
    return self.send(request, auth=auth, follow_redirects=follow_redirects)
           ~~~~~~~~~^^^^^^^^^^^^^^^^^^^^^^^^^^^^^^^^^^^^^^^^^^^^^^^^^^^^^^^
  File "/opt/hostedtoolcache/Python/3.13.7/x64/lib/python3.13/site-packages/httpx/_client.py", line 914, in send
    response = self._send_handling_auth(
        request,
    ...<2 lines>...
        history=[],
    )
  File "/opt/hostedtoolcache/Python/3.13.7/x64/lib/python3.13/site-packages/httpx/_client.py", line 942, in _send_handling_auth
    response = self._send_handling_redirects(
        request,
        follow_redirects=follow_redirects,
        history=history,
    )
  File "/opt/hostedtoolcache/Python/3.13.7/x64/lib/python3.13/site-packages/httpx/_client.py", line 979, in _send_handling_redirects
    response = self._send_single_request(request)
  File "/opt/hostedtoolcache/Python/3.13.7/x64/lib/python3.13/site-packages/httpx/_client.py", line 1014, in _send_single_request
    response = transport.handle_request(request)
  File "/opt/hostedtoolcache/Python/3.13.7/x64/lib/python3.13/site-packages/httpx/_transports/default.py", line 249, in handle_request
    with map_httpcore_exceptions():
         ~~~~~~~~~~~~~~~~~~~~~~~^^
  File "/opt/hostedtoolcache/Python/3.13.7/x64/lib/python3.13/contextlib.py", line 162, in __exit__
    self.gen.throw(value)
    ~~~~~~~~~~~~~~^^^^^^^
  File "/opt/hostedtoolcache/Python/3.13.7/x64/lib/python3.13/site-packages/httpx/_transports/default.py", line 118, in map_httpcore_exceptions
    raise mapped_exc(message) from exc
httpx.ConnectError: [Errno 104] Connection reset by peer
2025-09-22 06:40:38,533 - __main__ - ERROR - Error: Frame 4354 from episode 27 not found.
2025-09-22 06:40:38,533 - __main__ - ERROR - ✖ Error processing frame
2025-09-22 06:43:04,186 - src.frames_util - ERROR - Request error while downloading frame 3823 from episode 10: [Errno 104] Connection reset by peer
Traceback (most recent call last):
  File "/opt/hostedtoolcache/Python/3.13.7/x64/lib/python3.13/site-packages/httpx/_transports/default.py", line 101, in map_httpcore_exceptions
    yield
  File "/opt/hostedtoolcache/Python/3.13.7/x64/lib/python3.13/site-packages/httpx/_transports/default.py", line 250, in handle_request
    resp = self._pool.handle_request(req)
  File "/opt/hostedtoolcache/Python/3.13.7/x64/lib/python3.13/site-packages/httpcore/_sync/connection_pool.py", line 256, in handle_request
    raise exc from None
  File "/opt/hostedtoolcache/Python/3.13.7/x64/lib/python3.13/site-packages/httpcore/_sync/connection_pool.py", line 236, in handle_request
    response = connection.handle_request(
        pool_request.request
    )
  File "/opt/hostedtoolcache/Python/3.13.7/x64/lib/python3.13/site-packages/httpcore/_sync/connection.py", line 101, in handle_request
    raise exc
  File "/opt/hostedtoolcache/Python/3.13.7/x64/lib/python3.13/site-packages/httpcore/_sync/connection.py", line 78, in handle_request
    stream = self._connect(request)
  File "/opt/hostedtoolcache/Python/3.13.7/x64/lib/python3.13/site-packages/httpcore/_sync/connection.py", line 156, in _connect
    stream = stream.start_tls(**kwargs)
  File "/opt/hostedtoolcache/Python/3.13.7/x64/lib/python3.13/site-packages/httpcore/_backends/sync.py", line 154, in start_tls
    with map_exceptions(exc_map):
         ~~~~~~~~~~~~~~^^^^^^^^^
  File "/opt/hostedtoolcache/Python/3.13.7/x64/lib/python3.13/contextlib.py", line 162, in __exit__
    self.gen.throw(value)
    ~~~~~~~~~~~~~~^^^^^^^
  File "/opt/hostedtoolcache/Python/3.13.7/x64/lib/python3.13/site-packages/httpcore/_exceptions.py", line 14, in map_exceptions
    raise to_exc(exc) from exc
httpcore.ConnectError: [Errno 104] Connection reset by peer

The above exception was the direct cause of the following exception:

Traceback (most recent call last):
  File "/home/runner/work/rand-frieren/rand-frieren/src/frames_util.py", line 61, in download_frame
    response = client.get(frame_url)
  File "/opt/hostedtoolcache/Python/3.13.7/x64/lib/python3.13/site-packages/httpx/_client.py", line 1053, in get
    return self.request(
           ~~~~~~~~~~~~^
        "GET",
        ^^^^^^
    ...<7 lines>...
        extensions=extensions,
        ^^^^^^^^^^^^^^^^^^^^^^
    )
    ^
  File "/opt/hostedtoolcache/Python/3.13.7/x64/lib/python3.13/site-packages/httpx/_client.py", line 825, in request
    return self.send(request, auth=auth, follow_redirects=follow_redirects)
           ~~~~~~~~~^^^^^^^^^^^^^^^^^^^^^^^^^^^^^^^^^^^^^^^^^^^^^^^^^^^^^^^
  File "/opt/hostedtoolcache/Python/3.13.7/x64/lib/python3.13/site-packages/httpx/_client.py", line 914, in send
    response = self._send_handling_auth(
        request,
    ...<2 lines>...
        history=[],
    )
  File "/opt/hostedtoolcache/Python/3.13.7/x64/lib/python3.13/site-packages/httpx/_client.py", line 942, in _send_handling_auth
    response = self._send_handling_redirects(
        request,
        follow_redirects=follow_redirects,
        history=history,
    )
  File "/opt/hostedtoolcache/Python/3.13.7/x64/lib/python3.13/site-packages/httpx/_client.py", line 979, in _send_handling_redirects
    response = self._send_single_request(request)
  File "/opt/hostedtoolcache/Python/3.13.7/x64/lib/python3.13/site-packages/httpx/_client.py", line 1014, in _send_single_request
    response = transport.handle_request(request)
  File "/opt/hostedtoolcache/Python/3.13.7/x64/lib/python3.13/site-packages/httpx/_transports/default.py", line 249, in handle_request
    with map_httpcore_exceptions():
         ~~~~~~~~~~~~~~~~~~~~~~~^^
  File "/opt/hostedtoolcache/Python/3.13.7/x64/lib/python3.13/contextlib.py", line 162, in __exit__
    self.gen.throw(value)
    ~~~~~~~~~~~~~~^^^^^^^
  File "/opt/hostedtoolcache/Python/3.13.7/x64/lib/python3.13/site-packages/httpx/_transports/default.py", line 118, in map_httpcore_exceptions
    raise mapped_exc(message) from exc
httpx.ConnectError: [Errno 104] Connection reset by peer
2025-09-22 06:43:04,189 - __main__ - ERROR - Error: Frame 3823 from episode 10 not found.
2025-09-22 06:43:04,189 - __main__ - ERROR - ✖ Error processing frame
2025-10-24 03:33:24,958 - src.poster - ERROR - ✖ Error posting frame: Client error '400 Bad Request' for url 'https://graph.facebook.com/v21.0//me/photos?access_token=EAAMplsD3FFQBO9dn0XRGPN7Cx41kiuvXbA8fyZB9u9jvNPVrOksZAZBIKfftiLnReqc8AXVG3HpIfeHacIXOR9VaeJWF5oIZC9AKpXLj76PwkVMchfoCmOtUwkWzuvWKsidGi1osFocBi0xlponZC8jJzqwcnbcsp155zjaj4cTaZC4RudGec1ZCC9qJlZAAmHcZD&message=%5BRandom%5D+Frame%0A%0ASeason%3A+1%2C+Episode%3A+5%2C+Frame%3A+3660%0ATimestamp%3A+0%3A17%3A25.71%0A%0ADownload%3A+https%3A%2F%2Fjavaraf.github.io%2Fframe-view%2F%3Fseason%3D1%26episode%3D5%26frame%3D3660%0A'
For more information check: https://developer.mozilla.org/en-US/docs/Web/HTTP/Status/400
2025-10-24 03:33:24,958 - __main__ - ERROR - ✖ Failed to post frame data
2025-10-24 03:35:30,875 - src.poster - ERROR - ✖ Error posting frame: Client error '400 Bad Request' for url 'https://graph.facebook.com/v21.0//me/photos?access_token=EAAMplsD3FFQBO9dn0XRGPN7Cx41kiuvXbA8fyZB9u9jvNPVrOksZAZBIKfftiLnReqc8AXVG3HpIfeHacIXOR9VaeJWF5oIZC9AKpXLj76PwkVMchfoCmOtUwkWzuvWKsidGi1osFocBi0xlponZC8jJzqwcnbcsp155zjaj4cTaZC4RudGec1ZCC9qJlZAAmHcZD&message=%5BRandom%5D+Frame%0A%0ASeason%3A+1%2C+Episode%3A+22%2C+Frame%3A+1098%0ATimestamp%3A+0%3A05%3A13.71%0A%0ADownload%3A+https%3A%2F%2Fjavaraf.github.io%2Fframe-view%2F%3Fseason%3D1%26episode%3D22%26frame%3D1098%0A'
For more information check: https://developer.mozilla.org/en-US/docs/Web/HTTP/Status/400
2025-10-24 03:35:30,875 - __main__ - ERROR - ✖ Failed to post frame data
2025-10-24 03:37:36,804 - src.poster - ERROR - ✖ Error posting frame: Client error '400 Bad Request' for url 'https://graph.facebook.com/v21.0//me/photos?access_token=EAAMplsD3FFQBO9dn0XRGPN7Cx41kiuvXbA8fyZB9u9jvNPVrOksZAZBIKfftiLnReqc8AXVG3HpIfeHacIXOR9VaeJWF5oIZC9AKpXLj76PwkVMchfoCmOtUwkWzuvWKsidGi1osFocBi0xlponZC8jJzqwcnbcsp155zjaj4cTaZC4RudGec1ZCC9qJlZAAmHcZD&message=%5BRandom%5D+Frame%0A%0ASeason%3A+1%2C+Episode%3A+18%2C+Frame%3A+1443%0ATimestamp%3A+0%3A06%3A52.28%0A%0ADownload%3A+https%3A%2F%2Fjavaraf.github.io%2Fframe-view%2F%3Fseason%3D1%26episode%3D18%26frame%3D1443%0A'
For more information check: https://developer.mozilla.org/en-US/docs/Web/HTTP/Status/400
2025-10-24 03:37:36,804 - __main__ - ERROR - ✖ Failed to post frame data
2025-10-24 03:39:42,912 - src.poster - ERROR - ✖ Error posting frame: Client error '400 Bad Request' for url 'https://graph.facebook.com/v21.0//me/photos?access_token=EAAMplsD3FFQBO9dn0XRGPN7Cx41kiuvXbA8fyZB9u9jvNPVrOksZAZBIKfftiLnReqc8AXVG3HpIfeHacIXOR9VaeJWF5oIZC9AKpXLj76PwkVMchfoCmOtUwkWzuvWKsidGi1osFocBi0xlponZC8jJzqwcnbcsp155zjaj4cTaZC4RudGec1ZCC9qJlZAAmHcZD&message=%5BRandom%5D+Frame%0A%0ASeason%3A+1%2C+Episode%3A+25%2C+Frame%3A+3126%0ATimestamp%3A+0%3A14%3A53.14%0A%0ADownload%3A+https%3A%2F%2Fjavaraf.github.io%2Fframe-view%2F%3Fseason%3D1%26episode%3D25%26frame%3D3126%0A'
For more information check: https://developer.mozilla.org/en-US/docs/Web/HTTP/Status/400
2025-10-24 03:39:42,913 - __main__ - ERROR - ✖ Failed to post frame data
2025-10-24 03:41:49,060 - src.poster - ERROR - ✖ Error posting frame: Client error '400 Bad Request' for url 'https://graph.facebook.com/v21.0//me/photos?access_token=EAAMplsD3FFQBO9dn0XRGPN7Cx41kiuvXbA8fyZB9u9jvNPVrOksZAZBIKfftiLnReqc8AXVG3HpIfeHacIXOR9VaeJWF5oIZC9AKpXLj76PwkVMchfoCmOtUwkWzuvWKsidGi1osFocBi0xlponZC8jJzqwcnbcsp155zjaj4cTaZC4RudGec1ZCC9qJlZAAmHcZD&message=%5BRandom%5D+Frame%0A%0ASeason%3A+1%2C+Episode%3A+25%2C+Frame%3A+210%0ATimestamp%3A+0%3A01%3A00.00%0A%0ADownload%3A+https%3A%2F%2Fjavaraf.github.io%2Fframe-view%2F%3Fseason%3D1%26episode%3D25%26frame%3D210%0A'
For more information check: https://developer.mozilla.org/en-US/docs/Web/HTTP/Status/400
2025-10-24 03:41:49,060 - __main__ - ERROR - ✖ Failed to post frame data
2025-10-24 03:43:54,755 - src.poster - ERROR - ✖ Error posting frame: Client error '400 Bad Request' for url 'https://graph.facebook.com/v21.0//me/photos?access_token=EAAMplsD3FFQBO9dn0XRGPN7Cx41kiuvXbA8fyZB9u9jvNPVrOksZAZBIKfftiLnReqc8AXVG3HpIfeHacIXOR9VaeJWF5oIZC9AKpXLj76PwkVMchfoCmOtUwkWzuvWKsidGi1osFocBi0xlponZC8jJzqwcnbcsp155zjaj4cTaZC4RudGec1ZCC9qJlZAAmHcZD&message=%5BRandom%5D+Frame%0A%0ASeason%3A+1%2C+Episode%3A+1%2C+Frame%3A+3773%0ATimestamp%3A+0%3A17%3A58.00%0A%0ADownload%3A+https%3A%2F%2Fjavaraf.github.io%2Fframe-view%2F%3Fseason%3D1%26episode%3D1%26frame%3D3773%0A'
For more information check: https://developer.mozilla.org/en-US/docs/Web/HTTP/Status/400
2025-10-24 03:43:54,755 - __main__ - ERROR - ✖ Failed to post frame data
2025-10-24 03:46:00,907 - src.poster - ERROR - ✖ Error posting frame: Client error '400 Bad Request' for url 'https://graph.facebook.com/v21.0//me/photos?access_token=EAAMplsD3FFQBO9dn0XRGPN7Cx41kiuvXbA8fyZB9u9jvNPVrOksZAZBIKfftiLnReqc8AXVG3HpIfeHacIXOR9VaeJWF5oIZC9AKpXLj76PwkVMchfoCmOtUwkWzuvWKsidGi1osFocBi0xlponZC8jJzqwcnbcsp155zjaj4cTaZC4RudGec1ZCC9qJlZAAmHcZD&message=%5BRandom%5D+Frame%0A%0ASeason%3A+1%2C+Episode%3A+15%2C+Frame%3A+691%0ATimestamp%3A+0%3A03%3A17.42%0A%0ADownload%3A+https%3A%2F%2Fjavaraf.github.io%2Fframe-view%2F%3Fseason%3D1%26episode%3D15%26frame%3D691%0A'
For more information check: https://developer.mozilla.org/en-US/docs/Web/HTTP/Status/400
2025-10-24 03:46:00,907 - __main__ - ERROR - ✖ Failed to post frame data
2025-10-24 03:48:07,005 - src.poster - ERROR - ✖ Error posting frame: Client error '400 Bad Request' for url 'https://graph.facebook.com/v21.0//me/photos?access_token=EAAMplsD3FFQBO9dn0XRGPN7Cx41kiuvXbA8fyZB9u9jvNPVrOksZAZBIKfftiLnReqc8AXVG3HpIfeHacIXOR9VaeJWF5oIZC9AKpXLj76PwkVMchfoCmOtUwkWzuvWKsidGi1osFocBi0xlponZC8jJzqwcnbcsp155zjaj4cTaZC4RudGec1ZCC9qJlZAAmHcZD&message=%5BRandom%5D+Frame%0A%0ASeason%3A+1%2C+Episode%3A+7%2C+Frame%3A+1261%0ATimestamp%3A+0%3A06%3A00.28%0A%0ADownload%3A+https%3A%2F%2Fjavaraf.github.io%2Fframe-view%2F%3Fseason%3D1%26episode%3D7%26frame%3D1261%0A'
For more information check: https://developer.mozilla.org/en-US/docs/Web/HTTP/Status/400
2025-10-24 03:48:07,005 - __main__ - ERROR - ✖ Failed to post frame data
2025-10-24 03:50:13,034 - src.poster - ERROR - ✖ Error posting frame: Client error '400 Bad Request' for url 'https://graph.facebook.com/v21.0//me/photos?access_token=EAAMplsD3FFQBO9dn0XRGPN7Cx41kiuvXbA8fyZB9u9jvNPVrOksZAZBIKfftiLnReqc8AXVG3HpIfeHacIXOR9VaeJWF5oIZC9AKpXLj76PwkVMchfoCmOtUwkWzuvWKsidGi1osFocBi0xlponZC8jJzqwcnbcsp155zjaj4cTaZC4RudGec1ZCC9qJlZAAmHcZD&message=%5BRandom%5D+Frame%0A%0ASeason%3A+1%2C+Episode%3A+20%2C+Frame%3A+2860%0ATimestamp%3A+0%3A13%3A37.14%0A%0ADownload%3A+https%3A%2F%2Fjavaraf.github.io%2Fframe-view%2F%3Fseason%3D1%26episode%3D20%26frame%3D2860%0A'
For more information check: https://developer.mozilla.org/en-US/docs/Web/HTTP/Status/400
2025-10-24 03:50:13,034 - __main__ - ERROR - ✖ Failed to post frame data
2025-10-24 03:52:18,704 - src.poster - ERROR - ✖ Error posting frame: Client error '400 Bad Request' for url 'https://graph.facebook.com/v21.0//me/photos?access_token=EAAMplsD3FFQBO9dn0XRGPN7Cx41kiuvXbA8fyZB9u9jvNPVrOksZAZBIKfftiLnReqc8AXVG3HpIfeHacIXOR9VaeJWF5oIZC9AKpXLj76PwkVMchfoCmOtUwkWzuvWKsidGi1osFocBi0xlponZC8jJzqwcnbcsp155zjaj4cTaZC4RudGec1ZCC9qJlZAAmHcZD&message=%5BRandom%5D+Frame%0A%0ASeason%3A+1%2C+Episode%3A+11%2C+Frame%3A+1001%0ATimestamp%3A+0%3A04%3A46.00%0A%0ADownload%3A+https%3A%2F%2Fjavaraf.github.io%2Fframe-view%2F%3Fseason%3D1%26episode%3D11%26frame%3D1001%0A'
For more information check: https://developer.mozilla.org/en-US/docs/Web/HTTP/Status/400
2025-10-24 03:52:18,704 - __main__ - ERROR - ✖ Failed to post frame data
